Workbook

Sheet FOB
B1: VER 2/2026 | D1: FORMULÁRIO PEDIDO DISTRIBUIÇÃO D CORP (FOB) | F1: Vigência | H1: 46235
B2: Razão Social: | E2: CNPJ:
B3: I.E e I.M: | E3: CEP:
B4: Endereço: | E4: Instagram:
B5: Horário de entrega: | E5: Data Aniversario:
B6: Bairro: | E6: Cidade e Estado:
B7: Tel e Cel: | E7: E-mail:
B8: Selecione ao lado a tabela a vista ou a prazo | D8: A VISTA
B9: Vendedor:
F11: PRODUTOS
F12: TOTAL A PRAZO | G12: =E201 -> 0
F13: TOTAL A VISTA | G13: =E203 -> 0
B14: LANÇAMENTOS
P15: PEDIDOS ACIMA DE R$ 5.000,00
B16: CÓDIGO | C16: COD. DE BARRAS | D16: Máquinas de Tosa Propetz | E16: QUANTIDADE | F16: VALOR A PRAZO | G16: IPI | H16: VALOR COM IPI | I16: TOTAL S/ IPI | J16: TOTAL PRODUTOS | K16: VALOR A VISTA | L16: VALOR C/ IPI | M16: TOTAL S/ IPI | N16: TOTAL PRODUTOS | P16: VALOR A PRAZO | Q16: VALOR A VISTA | R16: PROMO A PRAZO | S16: PRAZO PROMO + IPI | T16: FOB A PRAZO COM IPI | U16: DIF IPI A PRAZO | V16: FOB A VISTA S/ IPI | W16: DIF IPI A VISTA | X16: FOB A VISTA C/ IPI | Y16: TOTAL A VISTA | Z16: TOTAL PROMO S/ DESC | AA16: VALOR DESC | AB16: TOTAL PROMO A PRAZO | AC16: TOTAL PROMO A VISTA | AD16: DESCONTO PROMO
B17: MP3-CF1X-100 | C17: 7898670766103 | D17: Máquina De Tosa PLUMA Propetz VERDE Profissional, Bivolt | E17: 0 | F17: =IF($D$8="A VISTA",Planilha2!B3,Planilha2!B3) -> 699 | G17: 0.13 | H17: =IFERROR(F17*(1+G17),#REF!) -> 789.87 | I17: =F17*E17 -> 0 | J17: =SUM(E17*H17) -> 0 | K17: =Planilha2!C3 -> 664.05 | L17: =K17*G17+K17 -> 750.3765 | M17: =K17*E17 -> 0 | N17: =L17*E17 -> 0 | P17: =F17 -> 699 | Q17: =K17 -> 664.05 | R17: =F17 -> 699 | S17: =H17 -> 789.87 | T17: =J17 -> 0 | U17: =R17*5% -> 34.95 | V17: =R17-U17 -> 664.05 | W17: =S17*5% -> 39.4935 | X17: =L17 -> 750.3765 | Y17: =X17*E17 -> 0 | Z17: 0 | AA17: =Z19*5% -> 0 | AB17: =S17*E17 -> 0 | AC17: =X17*E17 -> 0 | AD17: 0
B18: MP3-SF2X-100 | C18: 7898670767308 | D18: Máquina de tosa Pluma EVOLUTION SEM FIO Propetz verde profissional, bivolt | E18: 0 | F18: =IF($D$8="A VISTA",Planilha2!B12,Planilha2!B12) -> 940.5 | G18: 0.13 | H18: =IFERROR(F18*(1+G18),#REF!) -> 1062.765 | J18: =SUM(E18*H18) -> 0 | K18: =Planilha2!C12 -> 893.475 | L18: =K18*G18+K18 -> 1009.6268 | M18: =K18*E18 -> 0 | N18: =L18*E18 -> 0 | R18: =F18 -> 940.5 | S18: =H18 -> 1062.765 | T18: =J18 -> 0 | U18: =R18*5% -> 47.025 | V18: =R18-U18 -> 893.475 | W18: =S18*5% -> 53.13825 | X18: =L18 -> 1009.6268 | Y18: =X18*E18 -> 0 | Z18: =S18*E18 -> 0 | AA18: =Z18*5% -> 0 | AB18: =S18*E18 -> 0 | AC18: =X18*E18 -> 0
B19: MP4-SF1P-100 | C19: 7898670766110 | D19: Máquina De Tosa VOLARE Propetz SEM FIO Profissional, Bivolt | E19: 0 | F19: =IF($D$8="A VISTA",Planilha2!B4,Planilha2!B4) -> 1251 | G19: 0.13 | H19: =IFERROR(F19*(1+G19),#REF!) -> 1413.63 | I19: =F19*E19 -> 0 | J19: =SUM(E19*H19) -> 0 | K19: =Planilha2!C4 -> 1188.45 | L19: =K19*G19+K19 -> 1342.9485 | M19: =K19*E19 -> 0 | N19: =L19*E19 -> 0 | P19: =F19 -> 1251 | Q19: =K19 -> 1188.45 | R19: =F19 -> 1251 | S19: =H19 -> 1413.63 | T19: =J19 -> 0 | U19: =R19*5% -> 62.55 | V19: =R19-U19 -> 1188.45 | W19: =S19*5% -> 70.6815 | X19: =L19 -> 1342.9485 | Y19: =X19*E19 -> 0 | Z19: 0 | AA19: =Z20*5% -> 0 | AB19: =S19*E19 -> 0 | AC19: =X19*E19 -> 0 | AD19: =X19-AB19 -> 1342.9485
B20: MP5-510P-100 | C20: 7898670766127 | D20: Máquina De Tosa PRO7 Propetz PRETA - 5 em 1, Bivolt | E20: 0 | F20: =IF($D$8="A VISTA",Planilha2!B5,Planilha2!B5) -> 479.61 | G20: 0.13 | H20: =IFERROR(F20*(1+G20),#REF!) -> 541.9593 | I20: =F20*E20 -> 0 | J20: =SUM(E20*H20) -> 0 | K20: =Planilha2!C5 -> 455.6295 | L20: =K20*G20+K20 -> 514.86134 | M20: =K20*E20 -> 0 | N20: =L20*E20 -> 0 | P20: =H20 -> 541.9593 | Q20: =K20 -> 455.6295 | R20: =F20 -> 479.61 | S20: =H20 -> 541.9593 | T20: =J20 -> 0 | U20: =R20*5% -> 23.9805 | V20: =R20-U20 -> 455.6295 | W20: =S20*5% -> 27.097965 | X20: =L20 -> 514.86134 | Y20: =X20*E20 -> 0 | Z20: =S20*E20 -> 0 | AA20: =Z22*5% -> 0 | AB20: =S20*E20 -> 0 | AC20: =X20*E20 -> 0 | AD20: 0
B21: MP5-610X-100 | C21: 7898670767292 | D21: Máquina de tosa PRO7 X Propetz VERDE - 5 em 1, bivolt (cabo USB) | E21: 0 | F21: =IF($D$8="A VISTA",Planilha2!B13,Planilha2!B13) -> 369.55 | G21: 0.13 | H21: =IFERROR(F21*(1+G21),#REF!) -> 417.5915 | J21: =SUM(E21*H21) -> 0 | K21: =Planilha2!C13 -> 351.0725 | L21: =K21*G21+K21 -> 396.71193 | M21: =K21*E21 -> 0 | N21: =L21*E21 -> 0 | R21: =F21 -> 369.55 | S21: =H21 -> 417.5915 | T21: =J21 -> 0 | U21: =R21*5% -> 18.4775 | V21: =R21-U21 -> 351.0725 | W21: =S21*5% -> 20.879575 | X21: =L21 -> 396.71193 | Y21: =X21*E21 -> 0 | Z21: =S21*E21 -> 0 | AA21: =Z21*5% -> 0 | AB21: =S21*E21 -> 0 | AC21: =X21*E21 -> 0
B22: MP2-520X-100 | C22: 7898670765304 | D22: Máquina De Tosa PRO X Propetz VERDE - 4 em 1, Bivolt | E22: 0 | F22: =IF($D$8="A VISTA",Planilha2!B6,Planilha2!B6) -> 299 | G22: 0.13 | H22: =IFERROR(F22*(1+G22),#REF!) -> 337.87 | I22: =F22*E22 -> 0 | J22: =SUM(E22*H22) -> 0 | K22: =Planilha2!C6 -> 284.05 | L22: =K22*G22+K22 -> 320.9765 | M22: =K22*E22 -> 0 | N22: =L22*E22 -> 0 | P22: =H22 -> 337.87 | Q22: =K22 -> 284.05 | R22: =F22 -> 299 | S22: =H22 -> 337.87 | T22: =J22 -> 0 | U22: =R22*5% -> 14.95 | V22: =R22-U22 -> 284.05 | W22: =S22*5% -> 16.8935 | X22: =L22 -> 320.9765 | Y22: =X22*E22 -> 0 | Z22: =S22*E22 -> 0 | AA22: =Z23*5% -> 0 | AB22: =S22*E22 -> 0 | AC22: =X22*E22 -> 0 | AD22: 0
B23: MP1-320X-100 | C23: 7898670765335 | D23: Máquina De Tosa PRO X mini Propetz VERDE Acabamento, Bivolt | E23: 0 | F23: =IF($D$8="A VISTA",Planilha2!B7,Planilha2!B7) -> 166.28 | G23: 0.13 | H23: =IFERROR(F23*(1+G23),#REF!) -> 187.8964 | I23: =F23*E23 -> 0 | J23: =SUM(E23*H23) -> 0 | K23: =Planilha2!C7 -> 157.966 | L23: =K23*G23+K23 -> 178.50158 | M23: =K23*E23 -> 0 | N23: =L23*E23 -> 0 | P23: =H23 -> 187.8964 | Q23: =K23 -> 157.966 | R23: =F23 -> 166.28 | S23: =R23+R23*G23 -> 187.8964 | T23: =E23*S23 -> 0 | U23: =R23*5% -> 8.314 | V23: =R23-U23 -> 157.966 | W23: =S23*5% -> 9.39482 | X23: =S23-W23 -> 178.50158 | Y23: =X23*E23 -> 0 | Z23: =S23*E23 -> 0 | AA23: =Z23*5% -> 0 | AB23: =S23*E23 -> 0 | AC23: =X23*E23 -> 0 | AD23: =X23-AB23 -> 178.50158
B24: 8808-600-000 | C24: 7898670761054 | D24: Máquina de tosa PRO6 Propetz PRETA Profissional Acabamento, Bivolt | E24: 0 | F24: =IF($D$8="A VISTA",Planilha2!B8,Planilha2!B8) -> 448.11 | G24: 0.13 | H24: =IFERROR(F24*(1+G24),#REF!) -> 506.3643 | I24: =F24*E24 -> 0 | J24: =SUM(E24*H24) -> 0 | K24: =Planilha2!C8 -> 425.7045 | L24: =K24*G24+K24 -> 481.04609 | M24: =K24*E24 -> 0 | N24: =L24*E24 -> 0 | P24: =H24 -> 506.3643 | Q24: =K24 -> 425.7045 | R24: =F24 -> 448.11 | S24: =H24 -> 506.3643 | T24: =J24 -> 0 | U24: =R24*5% -> 22.4055 | V24: =R24-U24 -> 425.7045 | W24: =S24*5% -> 25.318215 | X24: =L24 -> 481.04609 | Y24: =X24*E24 -> 0 | Z24: =S24*E24 -> 0 | AA24: =Z24*5% -> 0 | AB24: =S24*E24 -> 0 | AC24: =X24*E24 -> 0 | AD24: 0
B25: 8808-320-000 | C25: 7898670761092 | D25: Máquina de tosa MO3 Propetz PINK , Lâmina de Cerâmica, Bivolt | E25: 0 | F25: =IF($D$8="A VISTA",Planilha2!B9,Planilha2!B9) -> 169.9 | G25: 0.13 | H25: =IFERROR(F25*(1+G25),#REF!) -> 191.987 | I25: =F25*E25 -> 0 | J25: =SUM(E25*H25) -> 0 | K25: =Planilha2!C9 -> 161.405 | L25: =K25*G25+K25 -> 182.38765 | M25: =K25*E25 -> 0 | N25: =L25*E25 -> 0 | P25: =H25 -> 191.987 | Q25: =K25 -> 161.405 | R25: =F25 -> 169.9 | S25: =H25 -> 191.987 | T25: =J25 -> 0 | U25: =R25*5% -> 8.495 | V25: =R25-U25 -> 161.405 | W25: =S25*5% -> 9.59935 | X25: =L25 -> 182.38765 | Y25: =X25*E25 -> 0 | Z25: =S25*E25 -> 0 | AA25: =Z25*5% -> 0 | AB25: =S25*E25 -> 0 | AC25: =X25*E25 -> 0 | AD25: 0
B26: 8808-300-000 | C26: 7898670761078 | D26: Máquina de tosa MO3 Propetz AZUL, Lâmina de Cerâmica, Bivolt | E26: 0 | F26: =IF($D$8="A VISTA",Planilha2!B10,Planilha2!B10) -> 169.9 | G26: 0.13 | H26: =IFERROR(F26*(1+G26),#REF!) -> 191.987 | I26: =F26*E26 -> 0 | J26: =SUM(E26*H26) -> 0 | K26: =Planilha2!C10 -> 161.405 | L26: =K26*G26+K26 -> 182.38765 | M26: =K26*E26 -> 0 | N26: =L26*E26 -> 0 | P26: =H26 -> 191.987 | Q26: =K26 -> 161.405 | R26: =F26 -> 169.9 | S26: =H26 -> 191.987 | T26: =J26 -> 0 | U26: =R26*5% -> 8.495 | V26: =R26-U26 -> 161.405 | W26: =S26*5% -> 9.59935 | X26: =L26 -> 182.38765 | Y26: =X26*E26 -> 0 | Z26: =S26*E26 -> 0 | AA26: =Z26*5% -> 0 | AB26: =S26*E26 -> 0 | AC26: =X26*E26 -> 0 | AD26: 0
B27: MP6-4CAP-100 | C27: 7898670767193 | D27: Máquina de tosa MO4 Propetz AZUL, Lâmina de Cerâmica, Bivolt (SEM ESTOQUE) | E27: 0 | F27: =IF($D$8="A VISTA",Planilha2!B11,Planilha2!B11) -> 189.9 | G27: 0.13 | H27: =IFERROR(F27*(1+G27),#REF!) -> 214.587 | I27: =F27*E27 -> 0 | J27: =SUM(E27*H27) -> 0 | K27: =Planilha2!C11 -> 180.405 | L27: =K27*G27+K27 -> 203.85765 | M27: =K27*E27 -> 0 | N27: =L27*E27 -> 0 | R27: =F27 -> 189.9 | S27: =H27 -> 214.587 | T27: =J27 -> 0 | U27: =R27*5% -> 9.495 | V27: =R27-U27 -> 180.405 | W27: =S27*5% -> 10.72935 | X27: =L27 -> 203.85765 | Y27: =X27*E27 -> 0 | Z27: =S27*E27 -> 0 | AA27: =Z27*5% -> 0 | AB27: =S27*E27 -> 0 | AC27: =X27*E27 -> 0 | AD27: 1
B28: CÓDIGO | C28: COD. DE BARRAS | D28: Secadores Aura Propetz | E28: QUANTIDADE | F28: VALOR A PRAZO | G28: IPI | H28: VALOR COM IPI | I28: TOTAL S/ IPI | J28: TOTAL PRODUTOS | K28: VALOR A VISTA | L28: VALOR C/ IPI | M28: TOTAL S/ IPI | N28: TOTAL PRODUTOS | R28: PROMO A PRAZO | S28: PRAZO PROMO + IPI | T28: FOB A PRAZO COM IPI | U28: DIF IPI A PRAZO | V28: FOB A VISTA S/ IPI | W28: DIF IPI A VISTA | X28: FOB A VISTA C/ IPI | Y28: TOTAL A VISTA | Z28: TOTAL PROMO S/ DESC | AA28: VALOR DESC | AB28: TOTAL PROMO A PRAZO | AC28: TOTAL PROMO A VISTA
B29: SEP1-100X-100 | C29: 7898670767285 | D29: Secador Aura Propetz 127V (SEM ESTOQUE) | E29: 0 | F29: =IF($D$8="A VISTA",Planilha2!B15,Planilha2!B15) -> 589 | G29: 0 | H29: =IFERROR(F29*(1+G29),#REF!) -> 589 | J29: =SUM(E29*H29) -> 0 | K29: =Planilha2!C15 -> 559.55 | L29: =K29*G29+K29 -> 559.55 | M29: =K29*E29 -> 0 | N29: =L29*E29 -> 0 | R29: =F29 -> 589 | S29: =H29 -> 589 | T29: =J29 -> 0 | U29: =R29*5% -> 29.45 | V29: =R29-U29 -> 559.55 | W29: =S29*5% -> 29.45 | X29: =L29 -> 559.55 | Y29: =X29*E29 -> 0 | Z29: =S29*E29 -> 0 | AA29: =Z29*5% -> 0 | AB29: =S29*E29 -> 0 | AC29: =X29*E29 -> 0
B30: SEP1-100X-200 | C30: 7898670767278 | D30: Secador Aura Propetz 220V (SEM ESTOQUE) | E30: 0 | F30: =IF($D$8="A VISTA",Planilha2!B16,Planilha2!B16) -> 589 | G30: 0 | H30: =IFERROR(F30*(1+G30),#REF!) -> 589 | J30: =SUM(E30*H30) -> 0 | K30: =Planilha2!C16 -> 559.55 | L30: =K30*G30+K30 -> 559.55 | M30: =K30*E30 -> 0 | N30: =L30*E30 -> 0 | R30: =F30 -> 589 | S30: =H30 -> 589 | T30: =J30 -> 0 | U30: =R30*5% -> 29.45 | V30: =R30-U30 -> 559.55 | W30: =S30*5% -> 29.45 | X30: =L30 -> 559.55 | Y30: =X30*E30 -> 0 | Z30: =S30*E30 -> 0 | AA30: =Z30*5% -> 0 | AB30: =S30*E30 -> 0 | AC30: =X30*E30 -> 0
B31: CÓDIGO | C31: COD. DE BARRAS | D31: Lâminas de Tosa Propetz - PRO 7 (5 em 1) | E31: QUANTIDADE | F31: VALOR A PRAZO | G31: IPI | H31: VALOR COM IPI | I31: TOTAL S/ IPI | J31: TOTAL PRODUTOS | K31: VALOR A VISTA | L31: VALOR C/ IPI | M31: TOTAL S/ IPI | N31: TOTAL PRODUTOS | P31: VALOR A PRAZO | Q31: VALOR A VISTA | R31: PROMO A PRAZO | S31: PRAZO PROMO + IPI | T31: FOB A PRAZO COM IPI | U31: DIF IPI A PRAZO | V31: FOB A VISTA S/ IPI | W31: DIF IPI A VISTA | X31: FOB A VISTA C/ IPI | Y31: TOTAL A VISTA | Z31: TOTAL PROMO S/ DESC | AA31: VALOR DESC | AB31: TOTAL PROMO A PRAZO | AC31: TOTAL PROMO A VISTA | AD31: DESCONTO PROMO
B32: L3P-CS830-200 | C32: 7898670766615 | D32: Lâmina de Tosa PRO7 Aço Inox Premium Regulável SLIM Nº 8 a Nº 30 Propetz | E32: 0 | F32: =IF($D$8="A VISTA",Planilha2!B18,Planilha2!B18) -> 177 | G32: 0.13 | H32: =IFERROR(F32*(1+G32),#REF!) -> 200.01 | I32: =F32*E32 -> 0 | J32: =SUM(E32*H32) -> 0 | K32: =Planilha2!C18 -> 168.15 | L32: =K32*G32+K32 -> 190.0095 | M32: =K32*E32 -> 0 | N32: =L32*E32 -> 0 | P32: =H32 -> 200.01 | Q32: =L32 -> 190.0095 | R32: =F32 -> 177 | S32: =H32 -> 200.01 | T32: =J32 -> 0 | U32: =R32*5% -> 8.85 | V32: =R32-U32 -> 168.15 | W32: =S32*5% -> 10.0005 | X32: =L32 -> 190.0095 | Y32: =X32*E32 -> 0 | Z32: =S32*E32 -> 0 | AA32: =Z32*5% -> 0 | AB32: =S32*E32 -> 0 | AC32: =X32*E32 -> 0 | AD32: =X32-AB32 -> 190.0095
B33: L3P-CF940-200 | C33: 7898670766141 | D33: Lâmina de Tosa PRO7 Aço Inox Premium Regulável ULTRA SLIM Nº 9 a Nº 40 Propetz | E33: 0 | F33: =IF($D$8="A VISTA",Planilha2!B19,Planilha2!B19) -> 177 | G33: 0.13 | H33: =IFERROR(F33*(1+G33),#REF!) -> 200.01 | I33: =F33*E33 -> 0 | J33: =SUM(E33*H33) -> 0 | K33: =Planilha2!C19 -> 168.15 | L33: =K33*G33+K33 -> 190.0095 | M33: =K33*E33 -> 0 | N33: =L33*E33 -> 0 | P33: =H33 -> 200.01 | Q33: =L33 -> 190.0095 | R33: =F33 -> 177 | S33: =H33 -> 200.01 | T33: =J33 -> 0 | U33: =R33*5% -> 8.85 | V33: =R33-U33 -> 168.15 | W33: =S33*5% -> 10.0005 | X33: =L33 -> 190.0095 | Y33: =X33*E33 -> 0 | Z33: =S33*E33 -> 0 | AA33: =Z33*5% -> 0 | AB33: =S33*E33 -> 0 | AC33: =X33*E33 -> 0 | AD33: =X33-AB33 -> 190.0095
B34: L3X-PS940-100 | C34: 7898670766165 | D34: Lâmina de Tosa PRO7 Linha X Regulável ULTRA SLIM Nº 9 a Nº 40 Propetz | E34: 0 | F34: =IF($D$8="A VISTA",Planilha2!B20,Planilha2!B20) -> 99.9 | G34: 0.13 | H34: =IFERROR(F34*(1+G34),#REF!) -> 112.887 | I34: =F34*E34 -> 0 | J34: =SUM(E34*H34) -> 0 | K34: =Planilha2!C20 -> 94.905 | L34: =K34*G34+K34 -> 107.24265 | M34: =K34*E34 -> 0 | N34: =L34*E34 -> 0 | P34: =H34 -> 112.887 | Q34: =L34 -> 107.24265 | R34: =PROMO!C137 -> 99.9 | S34: =H34 -> 112.887 | T34: =J34 -> 0 | U34: =R34*5% -> 4.995 | V34: =R34-U34 -> 94.905 | W34: =S34*5% -> 5.64435 | X34: =L34 -> 107.24265 | Y34: =X34*E34 -> 0 | Z34: =S34*E34 -> 0 | AA34: =Z34*5% -> 0 | AB34: =S34*E34 -> 0 | AC34: =X34*E34 -> 0 | AD34: =X34-AB34 -> 107.24265
B35: L3X-P7F-100 | C35: 7898670766172 | D35: Lâmina de Tosa PRO7 Linha X 7F Propetz | E35: 0 | F35: =IF($D$8="A VISTA",Planilha2!B21,Planilha2!B21) -> 149.9 | G35: 0.13 | H35: =IFERROR(F35*(1+G35),#REF!) -> 169.387 | I35: =F35*E35 -> 0 | J35: =SUM(E35*H35) -> 0 | K35: =Planilha2!C21 -> 142.405 | L35: =K35*G35+K35 -> 160.91765 | M35: =K35*E35 -> 0 | N35: =L35*E35 -> 0 | P35: =H35 -> 169.387 | Q35: =L35 -> 160.91765 | R35: =F35 -> 149.9 | S35: =H35 -> 169.387 | T35: =J35 -> 0 | U35: =R35*5% -> 7.495 | V35: =R35-U35 -> 142.405 | W35: =S35*5% -> 8.46935 | X35: =L35 -> 160.91765 | Y35: =X35*E35 -> 0 | Z35: =S35*E35 -> 0 | AA35: =Z35*5% -> 0 | AB35: =S35*E35 -> 0 | AC35: =X35*E35 -> 0 | AD35: =X35-AB35 -> 160.91765
B36: L3X-P4F-100 | C36: 7898670766189 | D36: Lâmina de Tosa PRO7 Linha X 4F Propetz | E36: 0 | F36: =IF($D$8="A VISTA",Planilha2!B22,Planilha2!B22) -> 192.9 | G36: 0.13 | H36: =IFERROR(F36*(1+G36),#REF!) -> 217.977 | I36: =F36*E36 -> 0 | J36: =SUM(E36*H36) -> 0 | K36: =Planilha2!C22 -> 183.255 | L36: =K36*G36+K36 -> 207.07815 | M36: =K36*E36 -> 0 | N36: =L36*E36 -> 0 | P36: =H36 -> 217.977 | Q36: =L36 -> 207.07815 | R36: =F36 -> 192.9 | S36: =H36 -> 217.977 | T36: =J36 -> 0 | U36: =R36*5% -> 9.645 | V36: =R36-U36 -> 183.255 | W36: =S36*5% -> 10.89885 | X36: =L36 -> 207.07815 | Y36: =X36*E36 -> 0 | Z36: =S36*E36 -> 0 | AA36: =Z36*5% -> 0 | AB36: =S36*E36 -> 0 | AC36: =X36*E36 -> 0 | AD36: =X36-AB36 -> 207.07815
B37: L3X-P5F-100 | C37: 7898670766349 | D37: Lâmina de Tosa PRO7 Linha X 5F Propetz | E37: 0 | F37: =IF($D$8="A VISTA",Planilha2!B23,Planilha2!B23) -> 99.9 | G37: 0.13 | H37: =IFERROR(F37*(1+G37),#REF!) -> 112.887 | I37: =F37*E37 -> 0 | J37: =SUM(E37*H37) -> 0 | K37: =PROMO!C141 -> 99.9 | L37: =K37*G37+K37 -> 112.887 | M37: =K37*E37 -> 0 | N37: =L37*E37 -> 0 | P37: =H37 -> 112.887 | Q37: =L37 -> 112.887 | R37: =PROMO!C141 -> 99.9 | S37: =R37+R37*G37 -> 112.887 | T37: =E37*S37 -> 0 | U37: =R37*5% -> 4.995 | V37: =R37-U37 -> 94.905 | W37: =S37*5% -> 5.64435 | X37: =S37-W37 -> 107.24265 | Y37: =X37*E37 -> 0 | Z37: =S37*E37 -> 0 | AA37: =Z37*5% -> 0 | AB37: =S37*E37 -> 0 | AC37: =X37*E37 -> 0 | AD37: =X37-AB37 -> 107.24265
B38: L3X-P6F-100 | C38: 7898670766356 | D38: Lâmina de Tosa PRO7 Linha X 6F Propetz | E38: 0 | F38: =IF($D$8="A VISTA",Planilha2!B24,Planilha2!B24) -> 99.9 | G38: 0.13 | H38: =IFERROR(F38*(1+G38),#REF!) -> 112.887 | I38: =F38*E38 -> 0 | J38: =SUM(E38*H38) -> 0 | K38: =PROMO!C140 -> 99.9 | L38: =K38*G38+K38 -> 112.887 | M38: =K38*E38 -> 0 | N38: =L38*E38 -> 0 | P38: =H38 -> 112.887 | Q38: =L38 -> 112.887 | R38: =PROMO!C140 -> 99.9 | S38: =R38+R38*G38 -> 112.887 | T38: =E38*S38 -> 0 | U38: =R38*5% -> 4.995 | V38: =R38-U38 -> 94.905 | W38: =S38*5% -> 5.64435 | X38: =S38-W38 -> 107.24265 | Y38: =X38*E38 -> 0 | Z38: =S38*E38 -> 0 | AA38: =Z38*5% -> 0 | AB38: =S38*E38 -> 0 | AC38: =X38*E38 -> 0 | AD38: =X38-AB38 -> 107.24265
B39: L3X-P3F-100 | C39: 7898670766301 | D39: Lâmina de Tosa PRO7 Linha X 3F Propetz | E39: 0 | F39: =IF($D$8="A VISTA",Planilha2!B25,Planilha2!B25) -> 149.9 | G39: 0.13 | H39: =IFERROR(F39*(1+G39),#REF!) -> 169.387 | I39: =F39*E39 -> 0 | J39: =SUM(E39*H39) -> 0 | K39: =Planilha2!C25 -> 142.405 | L39: =K39*G39+K39 -> 160.91765 | M39: =K39*E39 -> 0 | N39: =L39*E39 -> 0 | P39: =H39 -> 169.387 | Q39: =L39 -> 160.91765 | R39: =PROMO!C143 -> 149.9 | S39: =R39+R39*G39 -> 169.387 | T39: =E39*S39 -> 0 | U39: =R39*5% -> 7.495 | V39: =R39-U39 -> 142.405 | W39: =S39*5% -> 8.46935 | X39: =S39-W39 -> 160.91765 | Y39: =X39*E39 -> 0 | Z39: =S39*E39 -> 0 | AA39: =Z39*5% -> 0 | AB39: =S39*E39 -> 0 | AC39: =X39*E39 -> 0 | AD39: =X39-AB39 -> 160.91765
B40: L3P-CC045-100 | C40: 7898670766196 | D40: Lâmina de Tosa PRO7 Aço Inox Premium 45 Propetz Joyzee | E40: 0 | F40: =IF($D$8="A VISTA",Planilha2!B26,Planilha2!B26) -> 99.9 | G40: 0.13 | H40: =IFERROR(F40*(1+G40),#REF!) -> 112.887 | I40: =F40*E40 -> 0 | J40: =SUM(E40*H40) -> 0 | K40: =Planilha2!C26 -> 94.905 | L40: =K40*G40+K40 -> 107.24265 | M40: =K40*E40 -> 0 | N40: =L40*E40 -> 0 | P40: =H40 -> 112.887 | Q40: =L40 -> 107.24265 | R40: =PROMO!C138 -> 99.9 | S40: =R40+R40*G40 -> 112.887 | T40: =E40*S40 -> 0 | U40: =R40*5% -> 4.995 | V40: =R40-U40 -> 94.905 | W40: =S40*5% -> 5.64435 | X40: =S40-W40 -> 107.24265 | Y40: =X40*E40 -> 0 | Z40: =S40*E40 -> 0 | AA40: =Z40*5% -> 0 | AB40: =S40*E40 -> 0 | AC40: =X40*E40 -> 0 | AD40: =X40-AB40 -> 107.24265
B41: CÓDIGO | C41: COD. DE BARRAS | D41: Lâminas de Tosa Propetz - PRO 6/PRO X (4 em 1) | E41: QUANTIDADE | F41: VALOR A PRAZO | G41: IPI | H41: VALOR COM IPI | I41: TOTAL S/ IPI | J41: TOTAL PRODUTOS | K41: VALOR A VISTA | L41: VALOR C/ IPI | M41: TOTAL S/ IPI | N41: TOTAL PRODUTOS | P41: VALOR A PRAZO | Q41: VALOR A VISTA | R41: PROMO A PRAZO | S41: PRAZO PROMO + IPI | T41: FOB A PRAZO COM IPI | U41: DIF IPI A PRAZO | V41: FOB A VISTA S/ IPI | W41: DIF IPI A VISTA | X41: FOB A VISTA C/ IPI | Y41: TOTAL A VISTA | Z41: TOTAL PROMO S/ DESC | AA41: VALOR DESC | AB41: TOTAL PROMO A PRAZO | AC41: TOTAL PROMO A VISTA | AD41: DESCONTO PROMO
...

Sheet VALOR SUGERIDO
B1: PLANILHA DE VALORES SUGERIDOS FOB
A3: CÓDIGO | B3: Máquinas de Tosa Oster | C3: VALOR PRODUTO | F3: VALOR SUGERIDO | G3: MÍNIMO A VISTA | H3: % MÉDIA
A4: 78006150087 | B4: Máquina de Tosa A6 Slim Preta Bivolt Oster | C4: 1060 | F4: 2070.498 | G4: 1863.4482 | H4: =F4/C4-1 -> 0.9533
A5: 78006123087 | B5: Máquina de Tosa A6 Slim Roxa Purpura Bivolt Oster | C5: 1060 | F5: 2070.498 | G5: 1863.4482 | H5: =F5/C5-1 -> 0.9533
A6: 78006125087 | B6: Máquina de Tosa A6 Slim Patinhas Bivolt Oster | C6: 1085 | F6: 2117.027 | G6: 1905.3243 | H6: =F6/C6-1 -> 0.95117696
A7: 78006126087 | B7: Máquina de Tosa A6 Slim Azul Turquesa Bivolt Oster | C7: 1095 | F7: 2144.958 | G7: 1930.4622 | H7: =F7/C7-1 -> 0.95886575
A8: CÓDIGO | B8: Lâminas de Tosa Oster | C8: VALOR PRODUTO | F8: VALOR SUGERIDO | G8: MÍNIMO A VISTA | H8: % MÉDIA
A9: 78919006003 | B9: Lâmina de Tosa 50 Baixa Oster | C9: 159 | F9: 295.936 | G9: 266.3424 | H9: =F9/C9-1 -> 0.8612327
A10: 78919016003 | B10: Lâmina de Tosa 40 Baixa Oster | C10: 159 | F10: 295.936 | G10: 266.3424 | H10: =F10/C10-1 -> 0.8612327
A11: 78919026003 | B11: Lâmina de Tosa 30 Baixa Oster | C11: 159 | F11: 295.936 | G11: 266.3424 | H11: =F11/C11-1 -> 0.8612327
A12: 78919036003 | B12: Lâmina de Tosa 15 Baixa Oster | C12: 159 | F12: 295.936 | G12: 266.3424 | H12: =F12/C12-1 -> 0.8612327
A13: 78919046003 | B13: Lâmina de Tosa 10 Baixa Oster | C13: 159 | F13: 295.936 | G13: 266.3424 | H13: =F13/C13-1 -> 0.8612327
A14: 78919166003 | B14: Lâmina de Tosa 7F Média Oster | C14: 180 | F14: 334.526 | G14: 301.0734 | H14: =F14/C14-1 -> 0.85847778
A15: 78919106003 | B15: Lâmina de Tosa 5/8 Patinha Média Oster | C15: 180 | F15: 334.526 | G15: 301.0734 | H15: =F15/C15-1 -> 0.85847778
A16: 78919176003 | B16: Lâmina de Tosa 5F Alta Oster | C16: 231 | F16: 428.723 | G16: 385.8507 | H16: =F16/C16-1 -> 0.85594372
A17: 78919186003 | B17: Lâmina de Tosa 4F Alta Oster | C17: 231 | F17: 428.723 | G17: 385.8507 | H17: =F17/C17-1 -> 0.85594372
A18: 78919206003 | B18: Lâmina de Tosa 3F Super Alta Oster | C18: 283 | F18: 526.303 | G18: 473.6727 | H18: =F18/C18-1 -> 0.85972792
A19: CÓDIGO | B19: Máquinas de Tosa Propetz | C19: VALOR PRODUTO A PRAZO | D19: IPI | E19: PRODUTO+IPI | F19: VALOR SUGERIDO | G19: MÍNIMO A VISTA | H19: % MÉDIA
A20: MP3-CF1X-100 | B20: Máquina De Tosa PLUMA Propetz VERDE Profissional, Bivolt | C20: =Planilha2!B3 -> 699 | D20: =FOB!G17 -> 0.13 | E20: =C20*D20+C20 -> 789.87 | F20: 1320.5 | G20: 1181.5 | H20: =F20/E20-1 -> 0.67179409
A21: MP4-SF1P-100 | B21: Máquina De Tosa VOLARE Propetz PRETA Profissional, Bivolt | C21: =Planilha2!B4 -> 1251 | D21: =FOB!G19 -> 0.13 | E21: =C21*D21+C21 -> 1413.63 | F21: 2460.5 | G21: 2201.5 | H21: =F21/C21-1 -> 0.96682654
A22: MP5-510P-100 | B22: Máquina De Tosa PRO7 Propetz PRETA - 5 em 1, Bivolt | C22: =Planilha2!B5 -> 479.61 | D22: =FOB!G20 -> 0.13 | E22: =C22*D22+C22 -> 541.9593 | F22: 1034.55 | G22: 925.65 | H22: =F22/C22-1 -> 1.1570651
A23: MP2-520X-100 | B23: Máquina De Tosa PRO X Propetz VERDE - 4 em 1, Bivolt | C23: =Planilha2!B6 -> 299 | D23: =FOB!G22 -> 0.13 | E23: =C23*D23+C23 -> 337.87 | F23: 569.905 | G23: 509.915 | H23: =F23/C23-1 -> 0.90603679
A24: MP1-320X-100 | B24: Máquina De Tosa PRO X mini Propetz VERDE Acabamento, Bivolt | C24: =Planilha2!B7 -> 166.28 | D24: =FOB!G23 -> 0.13 | E24: =C24*D24+C24 -> 187.8964 | F24: 370.405 | G24: 331.415 | H24: =F24/C24-1 -> 1.227598
A25: 8808-600-000 | B25: Máquina de tosa PRO6 Propetz Preta Profissional Acabamento, Bivolt + Lamina 30 Abs | C25: =Planilha2!B8 -> 448.11 | D25: =FOB!G24 -> 0.13 | E25: =C25*D25+C25 -> 506.3643 | F25: 947.15 | G25: 847.45 | H25: =F25/C25-1 -> 1.1136551
A26: 8808-300-000 | B26: Máquina de tosa MO3 Propetz Azul, Lâmina de Cerâmica, Bivolt | C26: =Planilha2!B9 -> 169.9 | D26: =FOB!G25 -> 0.13 | E26: =C26*D26+C26 -> 191.987 | F26: 312.55 | G26: 279.65 | H26: =F26/C26-1 -> 0.83961154
A27: 8808-320-000 | B27: Máquina de tosa MO3 Propetz Rosa, Lâmina de Cerâmica, Bivolt | C27: =Planilha2!B10 -> 169.9 | D27: =FOB!G26 -> 0.13 | E27: =C27*D27+C27 -> 191.987 | F27: 312.55 | G27: 279.65 | H27: =F27/C27-1 -> 0.83961154
A28: MP6-4CAP-100 | B28: Máquina de tosa MO4 Propetz AZUL, Lâmina de Cerâmica, Bivolt | C28: =Planilha2!B11 -> 189.9 | D28: =FOB!G27 -> 0.13 | E28: =C28*D28+C28 -> 214.587 | F28: 377.15 | G28: 337.45 | H28: =F28/C28-1 -> 0.98604529
A29: MP3-SF2X-100 | B29: Máquina de tosa Pluma EVOLUTION Propetz verde profissional, bivolt | C29: =Planilha2!B12 -> 940.5 | D29: =FOB!G18 -> 0.13 | E29: =C29*D29+C29 -> 1062.765 | F29: 1795.5 | G29: 1606.5 | H29: =F29/C29-1 -> 0.90909091
A30: MP5-610X-100 | B30: Máquina de tosa Pro7 X Propetz verde - 5 em 1, bivolt | C30: =Planilha2!B13 -> 369.55 | D30: =FOB!G21 -> 0.13 | E30: =C30*D30+C30 -> 417.5915 | F30: 806.55 | G30: 721.65 | H30: =F30/C30-1 -> 1.1825193
A31: CÓDIGO | B31: Secadores Aura Propetz | C31: VALOR PRODUTO A PRAZO | D31: IPI | E31: PRODUTO+IPI | F31: VALOR SUGERIDO | G31: MÍNIMO A VISTA | H31: % MÉDIA
A32: SEP1-100X-100 | B32: Secador Aura Propetz 127V | C32: =Planilha2!B15 -> 589 | D32: =FOB!G29 -> 0 | E32: =C32*D32+C32 -> 589 | F32: 1320.5 | G32: 1181.5 | H32: =F32/C32-1 -> 1.2419355
A33: SEP1-100X-200 | B33: Secador Aura Propetz 220V | C33: =Planilha2!B16 -> 589 | D33: =FOB!G30 -> 0 | E33: =C33*D33+C33 -> 589 | F33: 1320.5 | G33: 1181.5 | H33: =F33/C33-1 -> 1.2419355
A34: CÓDIGO | B34: Lâminas de Tosa Propetz - PRO 7 (5 em 1) | C34: VALOR PRODUTO A PRAZO | D34: IPI | E34: PRODUTO+IPI | F34: VALOR SUGERIDO | G34: MÍNIMO A VISTA | H34: % MÉDIA
A35: L3P-CS830-200 | B35: Lâmina de Tosa PRO7 Aço Inox Premium Regulável SLIM Nº 8 a Nº 30 Propetz | C35: =Planilha2!B18 -> 177 | D35: =FOB!G32 -> 0.13 | E35: =C35*D35+C35 -> 200.01 | F35: 303.05 | G35: 271.15 | H35: =F35/C35-1 -> 0.71214689
A36: L3P-CF940-200 | B36: Lâmina de Tosa PRO7 Aço Inox Premium Regulável ULTRA SLIM Nº 9 a Nº 40 Propetz | C36: =Planilha2!B19 -> 177 | D36: =FOB!G33 -> 0.13 | E36: =C36*D36+C36 -> 200.01 | F36: 303.05 | G36: 271.15 | H36: =F36/C36-1 -> 0.71214689
A37: L3X-PS940-100 | B37: Lâmina de Tosa PRO7 PPS Linha X Regulável ULTRA SLIM Nº 9 a Nº 40 Propetz | C37: =Planilha2!B20 -> 99.9 | D37: =FOB!G34 -> 0.13 | E37: =C37*D37+C37 -> 112.887 | F37: 260.205 | G37: 232.815 | H37: =F37/C37-1 -> 1.6046547
A38: L3X-P7F-100 | B38: Lâmina de Tosa PRO7 PPS Linha X 7F Propetz | C38: =Planilha2!B21 -> 149.9 | D38: =FOB!G35 -> 0.13 | E38: =C38*D38+C38 -> 169.387 | F38: 277.305 | G38: 248.115 | H38: =F38/C38-1 -> 0.84993329
A39: L3X-P4F-100 | B39: Lâmina de Tosa PRO7 PPS Linha X 4F Propetz | C39: =Planilha2!B22 -> 192.9 | D39: =FOB!G36 -> 0.13 | E39: =C39*D39+C39 -> 217.977 | F39: 329.555 | G39: 294.865 | H39: =F39/C39-1 -> 0.70842405
A40: L3X-P5F-100 | B40: Lâmina de Tosa PRO7 PPS Linha X 5F Propetz | C40: =Planilha2!B23 -> 99.9 | D40: =FOB!G37 -> 0.13 | E40: =C40*D40+C40 -> 112.887 | F40: 298.205 | G40: 266.815 | H40: =F40/C40-1 -> 1.985035
A41: L3X-P6F-100 | B41: Lâmina de Tosa PRO7 PPS Linha X 6F Propetz | C41: =Planilha2!B24 -> 99.9 | D41: =FOB!G38 -> 0.13 | E41: =C41*D41+C41 -> 112.887 | F41: 287.755 | G41: 257.465 | H41: =F41/C41-1 -> 1.8804304
...

Sheet Planilha1
A1: REFERENCIA | B1: DESCRIÇÃO | C1: VALOR FOB | D1: VALOR CIF | E1: FOB DESC A VISTA | F1: CIF A PRAZO | G1: FOB A PRAZO | H1: DESCONTO CALCULADO | I1: FOB A VISTA | J1: CIF A PRAZO | K1: CIF A VISTA
A2: MP1-320X-100 | B2: Pro X Mini | C2: 159.9 | E2: 0.05 | F2: 0.035 | G2: =C2 -> 159.9 | H2: =C2*E2 -> 7.995 | I2: =C2-H2 -> 151.905 | J2: =C2+C2*F2 -> 165.4965 | K2: =C2-H2 -> 151.905
A3: L1SP-T50-200 | B3: Lâmina 50 Super Premium Titanium | C3: 157.93085 | E3: 0.05 | F3: 0.035 | G3: =C3 -> 157.93085 | H3: =C3*E3 -> 7.8965425 | I3: =C3-H3 -> 150.03431 | J3: =C3+C3*F3 -> 163.45843 | K3: =C3-H3 -> 150.03431
A4: L1SP-T40-200 | B4: Lâmina 40 Super Premium Titanium | C4: 162.3094 | E4: 0.05 | F4: 0.035 | G4: =C4 -> 162.3094 | H4: =C4*E4 -> 8.11547 | I4: =C4-H4 -> 154.19393 | J4: =C4+C4*F4 -> 167.99023 | K4: =C4-H4 -> 154.19393
A5: L1SP-T30-200 | B5: Lâmina 30 Super Premium Titanium | C5: 157.93085 | E5: 0.05 | F5: 0.035 | G5: =C5 -> 157.93085 | H5: =C5*E5 -> 7.8965425 | I5: =C5-H5 -> 150.03431 | J5: =C5+C5*F5 -> 163.45843 | K5: =C5-H5 -> 150.03431
A6: L1SP-T15-200 | B6: Lâmina 15 Super Premium Titanium | C6: 156.46785 | E6: 0.05 | F6: 0.035 | G6: =C6 -> 156.46785 | H6: =C6*E6 -> 7.8233925 | I6: =C6-H6 -> 148.64446 | J6: =C6+C6*F6 -> 161.94422 | K6: =C6-H6 -> 148.64446
A7: L1SP-T10-200 | B7: Lâmina 10 Super Premium Titanium | C7: 157.93085 | E7: 0.05 | F7: 0.035 | G7: =C7 -> 157.93085 | H7: =C7*E7 -> 7.8965425 | I7: =C7-H7 -> 150.03431 | J7: =C7+C7*F7 -> 163.45843 | K7: =C7-H7 -> 150.03431
A8: L1SP-T09-200 | B8: Lâmina 09 Super Premium Titanium | C8: 160.8464 | E8: 0.05 | F8: 0.035 | G8: =C8 -> 160.8464 | H8: =C8*E8 -> 8.04232 | I8: =C8-H8 -> 152.80408 | J8: =C8+C8*F8 -> 166.47602 | K8: =C8-H8 -> 152.80408
A9: L1SP-T7F-200 | B9: Lâmina 7F Super Premium Titanium | C9: 177.86945 | E9: 0.05 | F9: 0.035 | G9: =C9 -> 177.86945 | H9: =C9*E9 -> 8.8934725 | I9: =C9-H9 -> 168.97598 | J9: =C9+C9*F9 -> 184.09488 | K9: =C9-H9 -> 168.97598
A10: L1SP-T5F-200 | B10: Lâmina 5F Super Premium Titanium | C10: 201.2879 | E10: 0.05 | F10: 0.035 | G10: =C10 -> 201.2879 | H10: =C10*E10 -> 10.064395 | I10: =C10-H10 -> 191.22351 | J10: =C10+C10*F10 -> 208.33298 | K10: =C10-H10 -> 191.22351
A11: L1SP-T4F-200 | B11: Lâmina 4F Super Premium Titanium | C11: 231.154 | E11: 0.05 | F11: 0.035 | G11: =C11 -> 231.154 | H11: =C11*E11 -> 11.5577 | I11: =C11-H11 -> 219.5963 | J11: =C11+C11*F11 -> 239.24439 | K11: =C11-H11 -> 219.5963
A12: L1SP-T3F-200 | B12: Lâmina 3F Super Premium Titanium | C12: 271.38042 | E12: 0.05 | F12: 0.035 | G12: =C12 -> 271.38042 | H12: =C12*E12 -> 13.569021 | I12: =C12-H12 -> 257.8114 | J12: =C12+C12*F12 -> 280.87873 | K12: =C12-H12 -> 257.8114
A13: L2P-C50-100 | B13: EXTREME-EDGE 50# BLADE - Linha Premium | C13: 141.73335 | E13: 0.05 | F13: 0.035 | G13: =C13 -> 141.73335 | H13: =C13*E13 -> 7.0866675 | I13: =C13-H13 -> 134.64668 | J13: =C13+C13*F13 -> 146.69402 | K13: =C13-H13 -> 134.64668
... A60: 3PR-7TP-100 | B60: TESOURA PROFISSIONAL TUBARÃO 440C 7” PREMIUM – PROPETZ | C60: 179.9 | E60: 0.05 | F60: 0.035 | G60: =C60 -> 179.9 | H60: =C60*E60 -> 8.995 | I60: =C60-H60 -> 170.905 | J60: =C60+C60*F60 -> 186.1965 | K60: =C60-H60 -> 170.905

Sheet Planilha2
B1: PRAZO | C1: PRAZO - 5%
A2: Máquinas de Tosa Propetz | B2: VALOR DO PRODUTO | C2: VALOR DO PRODUTO | D2: CÓDIGO
A3: Máquina De Tosa PLUMA Propetz VERDE Profissional, Bivolt (LANÇAMENTO) | B3: 699 | C3: =-B3*5%+B3 -> 664.05 | D3: MP3-CF1X-100
A4: Máquina De Tosa VOLARE Propetz preta Profissional, Bivolt (LANÇAMENTO) | B4: 1251 | C4: =-B4*5%+B4 -> 1188.45 | D4: MP4-SF1P-100
A5: Máquina De Tosa PRO7 Propetz PRETA - 5 em 1, Bivolt (LANÇAMENTO) | B5: 479.61 | C5: =-B5*5%+B5 -> 455.6295 | D5: MP5-510P-100
A6: Máquina De Tosa PRO X Propetz VERDE - 4 em 1, Bivolt (LANÇAMENTO) | B6: 299 | C6: =-B6*5%+B6 -> 284.05 | D6: MP2-520X-100
A7: Máquina De Tosa PRO X mini Propetz VERDE Acabamento, Bivolt (LANÇAMENTO) | B7: 166.28 | C7: =-B7*5%+B7 -> 157.966 | D7: MP1-320X-100
A8: Máquina de tosa PRO6 Propetz PRETA Profissional Acabamento, Bivolt | B8: 448.11 | C8: =-B8*5%+B8 -> 425.7045 | D8: 8808-600-000
A9: Máquina de tosa MO3 Propetz PINK , Lâmina de Cerâmica, Bivolt | B9: 169.9 | C9: =-B9*5%+B9 -> 161.405 | D9: 8808-320-000
A10: Máquina de tosa MO3 Propetz AZUL, Lâmina de Cerâmica, Bivolt | B10: 169.9 | C10: =-B10*5%+B10 -> 161.405 | D10: 8808-300-000
A11: Máquina de tosa MO4 Propetz AZUL, Lâmina de Cerâmica, Bivolt | B11: 189.9 | C11: =-B11*5%+B11 -> 180.405 | D11: MP6-4CAP-100
A12: Máquina de tosa Pluma EVOLUTION Propetz verde profissional, bivolt | B12: 940.5 | C12: =-B12*5%+B12 -> 893.475 | D12: MP3-SF2X-100
A13: Máquina de tosa Pro7 X Propetz preta - 5 em 1, bivolt | B13: 369.55 | C13: =-B13*5%+B13 -> 351.0725 | D13: MP5-610X-100
A14: Secadores Aura Propetz | B14: FOB A PRAZO | C14: VALOR DO PRODUTO | D14: CÓDIGO
A15: Secador Aura Propetz 127V | B15: 589 | C15: =-B15*5%+B15 -> 559.55 | D15: SEP1-100X-100
A16: Secador Aura Propetz 220V | B16: 589 | C16: =-B16*5%+B16 -> 559.55 | D16: SEP1-100X-200
A17: Lâminas de Tosa Propetz - PRO 7 (5 em 1) | B17: FOB A PRAZO | C17: VALOR DO PRODUTO | D17: CÓDIGO
A18: Lâmina de Tosa Aço Inox Premium Regulável SLIM Nº 8 a Nº 30 Propetz (LANÇAMENTO) | B18: 177 | C18: =-B18*5%+B18 -> 168.15 | D18: L3P-CS830-200
A19: Lâmina de Tosa Aço Inox Premium Regulável ULTRA SLIM Nº 9 a Nº 40 Propetz (LANÇAMENTO) | B19: 177 | C19: =-B19*5%+B19 -> 168.15 | D19: L3P-CF940-200
A20: Lâmina de Tosa PPS Linha X Regulável ULTRA SLIM Nº 9 a Nº 40 Propetz (LANÇAMENTO) | B20: 99.9 | C20: =-B20*5%+B20 -> 94.905 | D20: L3X-PS940-100
A21: Lâmina de Tosa PPS Linha X 7F Propetz (LANÇAMENTO) | B21: 149.9 | C21: =-B21*5%+B21 -> 142.405 | D21: L3X-P7F-100
A22: Lâmina de Tosa PPS Linha X 4F Propetz (LANÇAMENTO) | B22: 192.9 | C22: =-B22*5%+B22 -> 183.255 | D22: L3X-P4F-100
A23: Lâmina de Tosa PPS Linha X 5F Propetz (LANÇAMENTO) | B23: 99.9 | C23: =-B23*5%+B23 -> 94.905 | D23: L3X-P5F-100
A24: Lâmina de Tosa PPS Linha X 6F Propetz (LANÇAMENTO) | B24: 99.9 | C24: =-B24*5%+B24 -> 94.905 | D24: L3X-P6F-100
A25: Lâmina de Tosa PPS Linha X 3F Propetz (LANÇAMENTO) | B25: 149.9 | C25: =-B25*5%+B25 -> 142.405 | D25: L3X-P3F-100
A26: Lâmina de Tosa Aço Inox Premium 45 Propetz (LANÇAMENTO) | B26: 99.9 | C26: =-B26*5%+B26 -> 94.905 | D26: L3P-CC045-100
A27: Lâminas de Tosa Propetz - PRO 6/PRO X (4 em 1) | B27: FOB A PRAZO | C27: VALOR DO PRODUTO | D27: CÓDIGO
A28: Lâmina de Tosa PPS Linha X Regulável SLIM Nº 9 a Nº 30 Propetz | B28: 87.9 | C28: =-B28*5%+B28 -> 83.505 | D28: L2APROXS-100
A29: Lâmina de Tosa PPS LINHA X Regulável ULTRA SLIM Nº 10 a Nº 40 Propetz | B29: 87.9 | C29: =-B29*5%+B29 -> 83.505 | D29: L2APROXUS-100
A30: Lâmina de Tosa PPS Linha X 7F PRO6 Propetz | B30: 125 | C30: =-B30*5%+B30 -> 118.75 | D30: L2AP67F-100
A31: Lâmina de Tosa PPS Linha X 4F PRO6 Propetz | B31: 172 | C31: =-B31*5%+B31 -> 163.4 | D31: L2AP64F-100
A32: Lâmina de Tosa PPS Linha X 5F PRO6 Propetz | B32: 159 | C32: =-B32*5%+B32 -> 151.05 | D32: L2AP65F-100
A33: Lâmina de Tosa PPS Linha X 3F PRO6 Propetz | B33: 160.3 | C33: =-B33*5%+B33 -> 152.285 | D33: L2AP63F-100
A34: Lamina de Tosa PPS Linha X 30 Propetz | B34: 122 | C34: =-B34*5%+B34 -> 115.9 | D34: L2AP630XB-200
A35: Lamina de Tosa Aço Inox Premium 30 Propetz | B35: 167 | C35: =-B35*5%+B35 -> 158.65 | D35: L2AP630SS-200
A36: Lâminas de Tosa Propetz - MO 3/PRO 4/PRO X mini | B36: FOB A PRAZO | C36: VALOR DO PRODUTO | D36: CÓDIGO
A37: Lâmina de Tosa PRO X mini Propetz de Nº0.25mm (LANÇAMENTO) | B37: 66.9 | C37: =-B37*5%+B37 -> 63.555 | D37: L2AP3-100
A38: Lâmina de Tosa PRO4 Propetz, N°0,25mm | B38: 79.9 | C38: =-B38*5%+B38 -> 75.905 | D38: L2AP4-100
A39: Lâmina de Tosa MO3 Propetz de Nº1.0mm | B39: 72.9 | C39: =-B39*5%+B39 -> 69.255 | D39: L2PMO3-100
A40: Cortante I de Cerâmica Lâminas Propetz - Para lâminas n.40 e n.50 | B40: 29.9 | C40: =-B40*5%+B40 -> 28.405 | D40: CL1CP-100
...

Sheet PROMO
A1: SKU | B1: DESCRIÇÃO | C1: VALOR
A2: 8808-600-000 | B2: PRO 6 SMART DIGITAL DETACHABLE BLADES CLIPPER BLACK | C2: 0 | D2: C2
A3: MP5-510P-100 | B3: PRO 7 preta premium | C3: 0 | D3: C3
A4: MP2-520X-100 | B4: PRO X Azul propetz | C4: 0 | D4: C4
A5: L2APROXS-100 | B5: SLIM BLADES CERAMIC 9#-30#ADVANCE PRO 6 | C5: 0 | D5: C5
A6: L2APROXUS-100 | B6: ULTRA-THIN BLADES CERAMIC 10#-40# ADVANCE PRO 6 | C6: 0 | D6: C6
A7: L2AP630XB-200 | B7: LAM. PRO 30#/10# - X Black | C7: 0 | D7: C7
A8: L2AP630SS-200 | B8: LAM. PRO 30#/10# - Premium Stainless Stell | C8: 0 | D8: C8
A9: L2AP67F-100 | B9: THICK BLADE ONLY FIT PRO6 CLIPPER 7FC (3MM) | C9: 0 | D9: C9
A10: L2AP65F-100 | B10: THICK BLADE ONLY FIT PRO6 CLIPPER 5FC (6MM) | C10: 133.56 | D10: C10
A11: L2AP64F-100 | B11: THICK BLADE ONLY FIT PRO6 CLIPPER 4FC (9MM) | C11: 0 | D11: C11
A12: L2AP63F-100 | B12: THICK BLADE ONLY FIT PRO6 CLIPPER 3FC (12MM) | C12: 160.3 | D12: C12
A13: MP1-320X-100 | B13: Pro X Mini | C13: 0 | D13: C13
... A30: L1SP-T4F-200 | B30: Lâmina 4F Super Premium Titanium | C30: 0 | D30: C30
A31: L1SP-T3F-200 | B31: Lâmina 3F Super Premium Titanium | C31: falso | D31: C31
A32: L2P-C50-100 | B32: EXTREME-EDGE 50# BLADE - Linha Premium | C32: 0 | D32: C32
A33: L2P-C40-100 | B33: EXTREME-EDGE 40# BLADE - Linha Premium | C33: 0 | D33: C33
A34: L2P-C15-100 | B34: EXTREME-EDGE 15 BLADE - Linha Premium | C34: 0 | D34: C34
A35: L2P-C10-100 | B35: EXTREME-EDGE 10 BLADE - Linha Premium | C35: 0 | D35: C35
A36: L2P-C09-100 | B36: EXTREME-EDGE 9 BLADE - Linha Premium | C36: 0 | D36: C36
A37: L2P-C30-100 | B37: EXTREME-EDGE 30 BLADE - Linha Premium | C37: 0 | D37: C37
A38: L2P-C7F-100 | B38: EXTREME-EDGE 7F BLADE - Linha Premium | C38: 0 | D38: C38
A39: L2P-C5F-100 | B39: EXTREME-EDGE 5F BLADE - Linha Premium | C39: 0 | D39: C39
A40: L2P-C4F-100 | B40: EXTREME-EDGE 4F BLADE - Linha Premium | C40: 0 | D40: C40
A41: L2P-C3F-100 | B41: EXTREME-EDGE 3F BLADE - Linha Premium | C41: falso | D41: C41
A42: CHPRO4BLACK | B42: BASE CARREGADORA PARA MAQUINA PRO4 PRETA PROPETZ (sem cabo) | C42: 0 | D42: C42
A43: PLUGPRO4 | B43: CABO ADAPTADOR PARA MAQUINA PRO4 PROPETZ (cabo) | C43: falso | D43: C43
A44: CHPRO6BLACK | B44: BASE CARREGADORA PARA MAQUINA PRO6 PRETA PROPETZ (sem cabo) | C44: 0 | D44: C44
A45: PLUGPRO6 | B45: CABO ADAPTADOR PARA MAQUINA PRO6 PROPETZ (cabo) | C45: 0 | D45: C45
A46: PLASTICBLADE1 | B46: GUIA DE LAMINA TITANIUM PROPETZ | C46: 0 | D46: C46
A47: TENSION1 | B47: MOLA DE LAMINA TITANIUM PROPETZ | C47: 0 | D47: C47
A48: BRACKET1 | B48: SOQUETE PARA LAMINA TITANIUM PROPETZ | C48: 0 | D48: C48
A49: SCREWBLADE1 | B49: PARAFUSO P; LAMINAS TITANIUM PROPETZ | C49: 0 | D49: C49
A50: CORDMO3 | B50: CABO USB MAQUINA MO3 PROPETZ | C50: 0 | D50: C50
A51: 5AK-65CA-100 | B51: TESOURA CURVA 6.5 ALUMÍNIO PROPETZ AKEMI - AZUL | C51: 0 | D51: C51
A52: 5AK-65CR-100 | B52: TESOURA CURVA 6.5 ALUMÍNIO PROPETZ AKEMI - ROSA | C52: 0 | D52: C52
A53: 5AK-70CA-100 | B53: TESOURA CURVA 7 ALUMÍNIO PROPETZ AKEMI - AZUL | C53: 0 | D53: C53
A54: 5AK-70CR-100 | B54: TESOURA CURVA 7 ALUMÍNIO PROPETZ AKEMI - ROSA | C54: 0 | D54: C54
A55: 2CRP-PR-100 | B55: Estojo X para 20 Tesouras Propetz | C55: 0 | D55: C55
... A67: E1GCA-200 | B67: Rasqueadeira Curva Grande Azul Propetz | C67: 0 | D67: C67
...

Sheet Planilha4
B1: 8808-600-000 | D1: 1CPP-PR-100
B2: MP5-510P-100 | D2: 1CRP-PR-100
B3: MP2-520X-100 | D3: 2CRP-PR-100
B4: L2APROXS-100 | D4: 3PR-7SDP-100
B5: L2APROXUS-100 | D5: 3PR-7TP-100
B6: L2AP630XB-200 | D6: 4PR-70C-CP-100
B7: L2AP630SS-200 | D7: 4PR-70R-CP-100
B8: L2AP67F-100 | D8: 4PR-70SDC-CP-100
B9: L2AP65F-100 | D9: 4PR-70SD-CP-100
B10: L2AP64F-100 | D10: 4PR-70TC-CP-100
B11: L2AP63F-100 | D11: 4PR-70T-CP-100
B12: MP1-320X-100 | D12: 4PR-75CC-CP-100
... B195: E1MCA-200 | D195: TENSION1

Sheet CONTROLE DE REVISOES
A1: REVISAO | B1: DATA | C1: RESPONSAVEL | D1: MODIFICACOES
A2: REV 01/2024 | B2: 45603 | C2: FERNANDO DIAS | D2: Definido um controle de versao do documento para melhor rastreabilidade
D3: Ocultada o combo de preco a vista e a prazo pois para os resultados oriundos da pesquisa se torna redundante
D4: Espelhado o valor da coluna B da Planilha 2 para a coluna F da Planilha FOB
D5: Espelhado o valor da coluna C da Planilha 2 para a coluna C de Valor Sugerido eliminando o retrabalho
D6: Ajustadas algumas categorias de produtos entre as planilhas
D7: Criado o campo preco a vista e a prazo para calcular os valores finais apos selecao de quantidades
D8: Linha C216 na Planilha FOB criada para demonstrar a diferenca entre preco total a prazo e total a vista
D9: Ajustes na visualizacao
D10: Congelada a linha 14 na planilha FOB, mantendo o cabecalho no topo e movimentando apenas os produtos abaixo
D11: Descongelada a linha 14 na planilha FOB
D12: Corrigidos 3 produtos que perderam a referência do preço
D13: Alterada a ordem do quadro geral com os somatórios a vista e a prazo ficando igual ao rodapé
A14: REV 02/2024 | B14: 45604 | C14: FERNANDO DIAS | D14: Inclusa coluna K na planilha FOB, valores referentes a coluna C da Planilha 2
D15: Ajuste em referências que foram perdidas na formatação e exclusão de alguns produtos
A16: REV 03/2024 | B16: 45607 | C16: FERNANDO DIAS | D16: Criada nova coluna com o total de valor a vista para soma dos valores totais com as quantidades
B17: 45609 | C17: FERNANDO DIAS | D17: Revisados os calculos, formulas e totalizadores e testados os resultados
A18: REV 01/2025 | B18: 45664 | C18: FERNANDO DIAS | D18: Criada coluna com valor total sem ipi
